Workbook

Sheet Selected_Schemes
A1: S_No | B1: Category | C1: Scheme_Code | D1: Scheme_Name | E1: AMC_Name | F1: Plan_Type | G1: Option_Type | H1: Selected | I1: Remarks | J1: NAV_Start_Date | K1: NAV_End_Date | L1: Five_Year_Eligible | M1: Eligibility_Remark
A2: 1 | B2: Large Cap Fund | C2: 118632 | D2: =_xlfn.XLOOKUP(tbl_Selected_Schemes[[#This Row],[Scheme_Code]],All_Schemes[Scheme_Code],All_Schemes[Scheme_Name],"Not Found",0) -> Nippon India Large Cap Fund - Direct Plan Growth Plan - Growth Option | E2: {=IFERROR(_xlfn.XLOOKUP(TRUE,ISNUMBER(SEARCH(Lists!$H$2:$H$30,D2)),Lists!$I$2:$I$30),"Check Manually")} -> Nippon India Mutual Fund | F2: Direct | G2: Growth | H2: Yes | J2: =_xlfn.XLOOKUP($C2,Eligibility_All!$B:$B,Eligibility_All!$D:$D,"Not Found",0) -> 41276 | K2: =_xlfn.XLOOKUP($C2,Eligibility_All!$B:$B,Eligibility_All!$E:$E,"Not Found",0) -> 46188 | L2: =_xlfn.XLOOKUP($C2,Eligibility_All!$B:$B,Eligibility_All!$F:$F,"Not Found",0) -> Yes | M2: =_xlfn.XLOOKUP($C2,Eligibility_All!$B:$B,Eligibility_All!$G:$G,"Not Found",0) -> Complete 5-year NAV history available
A3: 2 | B3: Large Cap Fund | C3: 120586 | D3: =_xlfn.XLOOKUP(tbl_Selected_Schemes[[#This Row],[Scheme_Code]],All_Schemes[Scheme_Code],All_Schemes[Scheme_Name],"Not Found",0) -> ICICI Prudential Large Cap Fund (erstwhile Bluechip Fund) - Direct Plan - Growth | E3: {=IFERROR(_xlfn.XLOOKUP(TRUE,ISNUMBER(SEARCH(Lists!$H$2:$H$30,D3)),Lists!$I$2:$I$30),"Check Manually")} -> ICICI Prudential Mutual Fund | F3: Direct | G3: Growth | H3: Yes | J3: =_xlfn.XLOOKUP($C3,Eligibility_All!$B:$B,Eligibility_All!$D:$D,"Not Found",0) -> 41276 | K3: =_xlfn.XLOOKUP($C3,Eligibility_All!$B:$B,Eligibility_All!$E:$E,"Not Found",0) -> 46188 | L3: =_xlfn.XLOOKUP($C3,Eligibility_All!$B:$B,Eligibility_All!$F:$F,"Not Found",0) -> Yes | M3: =_xlfn.XLOOKUP($C3,Eligibility_All!$B:$B,Eligibility_All!$G:$G,"Not Found",0) -> Complete 5-year NAV history available
A4: 3 | B4: Large Cap Fund | C4: 119018 | D4: =_xlfn.XLOOKUP(tbl_Selected_Schemes[[#This Row],[Scheme_Code]],All_Schemes[Scheme_Code],All_Schemes[Scheme_Name],"Not Found",0) -> HDFC Large Cap Fund - Growth Option - Direct Plan | E4: {=IFERROR(_xlfn.XLOOKUP(TRUE,ISNUMBER(SEARCH(Lists!$H$2:$H$30,D4)),Lists!$I$2:$I$30),"Check Manually")} -> HDFC Mutual Fund | F4: Direct | G4: Growth | H4: Yes | J4: =_xlfn.XLOOKUP($C4,Eligibility_All!$B:$B,Eligibility_All!$D:$D,"Not Found",0) -> 41275 | K4: =_xlfn.XLOOKUP($C4,Eligibility_All!$B:$B,Eligibility_All!$E:$E,"Not Found",0) -> 46188 | L4: =_xlfn.XLOOKUP($C4,Eligibility_All!$B:$B,Eligibility_All!$F:$F,"Not Found",0) -> Yes | M4: =_xlfn.XLOOKUP($C4,Eligibility_All!$B:$B,Eligibility_All!$G:$G,"Not Found",0) -> Complete 5-year NAV history available
A5: 4 | B5: Large Cap Fund | C5: 118269 | D5: =_xlfn.XLOOKUP(tbl_Selected_Schemes[[#This Row],[Scheme_Code]],All_Schemes[Scheme_Code],All_Schemes[Scheme_Name],"Not Found",0) -> CANARA ROBECO LARGE CAP FUND - DIRECT PLAN - GROWTH OPTION | E5: {=IFERROR(_xlfn.XLOOKUP(TRUE,ISNUMBER(SEARCH(Lists!$H$2:$H$30,D5)),Lists!$I$2:$I$30),"Check Manually")} -> Canara Robeco Mutual Fund | F5: Direct | G5: Growth | H5: Yes | J5: =_xlfn.XLOOKUP($C5,Eligibility_All!$B:$B,Eligibility_All!$D:$D,"Not Found",0) -> 41276 | K5: =_xlfn.XLOOKUP($C5,Eligibility_All!$B:$B,Eligibility_All!$E:$E,"Not Found",0) -> 46188 | L5: =_xlfn.XLOOKUP($C5,Eligibility_All!$B:$B,Eligibility_All!$F:$F,"Not Found",0) -> Yes | M5: =_xlfn.XLOOKUP($C5,Eligibility_All!$B:$B,Eligibility_All!$G:$G,"Not Found",0) -> Complete 5-year NAV history available
A6: 5 | B6: Large Cap Fund | C6: 119598 | D6: =_xlfn.XLOOKUP(tbl_Selected_Schemes[[#This Row],[Scheme_Code]],All_Schemes[Scheme_Code],All_Schemes[Scheme_Name],"Not Found",0) -> SBI Large Cap FUND-DIRECT PLAN -GROWTH | E6: {=IFERROR(_xlfn.XLOOKUP(TRUE,ISNUMBER(SEARCH(Lists!$H$2:$H$30,D6)),Lists!$I$2:$I$30),"Check Manually")} -> SBI Mutual Fund | F6: Direct | G6: Growth | H6: Yes | J6: =_xlfn.XLOOKUP($C6,Eligibility_All!$B:$B,Eligibility_All!$D:$D,"Not Found",0) -> 41276 | K6: =_xlfn.XLOOKUP($C6,Eligibility_All!$B:$B,Eligibility_All!$E:$E,"Not Found",0) -> 46188 | L6: =_xlfn.XLOOKUP($C6,Eligibility_All!$B:$B,Eligibility_All!$F:$F,"Not Found",0) -> Yes | M6: =_xlfn.XLOOKUP($C6,Eligibility_All!$B:$B,Eligibility_All!$G:$G,"Not Found",0) -> Complete 5-year NAV history available
A7: 6 | B7: Large & Mid Cap Fund | C7: 147704 | D7: =_xlfn.XLOOKUP(tbl_Selected_Schemes[[#This Row],[Scheme_Code]],All_Schemes[Scheme_Code],All_Schemes[Scheme_Name],"Not Found",0) -> Motilal Oswal Large and Midcap Fund - Direct Plan Growth | E7: {=IFERROR(_xlfn.XLOOKUP(TRUE,ISNUMBER(SEARCH(Lists!$H$2:$H$30,D7)),Lists!$I$2:$I$30),"Check Manually")} -> Motilal Oswal Mutual Fund | F7: Direct | G7: Growth | H7: Yes | J7: =_xlfn.XLOOKUP($C7,Eligibility_All!$B:$B,Eligibility_All!$D:$D,"Not Found",0) -> 43760 | K7: =_xlfn.XLOOKUP($C7,Eligibility_All!$B:$B,Eligibility_All!$E:$E,"Not Found",0) -> 46188 | L7: =_xlfn.XLOOKUP($C7,Eligibility_All!$B:$B,Eligibility_All!$F:$F,"Not Found",0) -> Yes | M7: =_xlfn.XLOOKUP($C7,Eligibility_All!$B:$B,Eligibility_All!$G:$G,"Not Found",0) -> Complete 5-year NAV history available
A8: 7 | B8: Large & Mid Cap Fund | C8: 120357 | D8: =_xlfn.XLOOKUP(tbl_Selected_Schemes[[#This Row],[Scheme_Code]],All_Schemes[Scheme_Code],All_Schemes[Scheme_Name],"Not Found",0) -> Invesco India Large & Mid Cap Fund - Direct Plan - Growth | E8: {=IFERROR(_xlfn.XLOOKUP(TRUE,ISNUMBER(SEARCH(Lists!$H$2:$H$30,D8)),Lists!$I$2:$I$30),"Check Manually")} -> Invesco Mutual Fund | F8: Direct | G8: Growth | H8: Yes | J8: =_xlfn.XLOOKUP($C8,Eligibility_All!$B:$B,Eligibility_All!$D:$D,"Not Found",0) -> 41276 | K8: =_xlfn.XLOOKUP($C8,Eligibility_All!$B:$B,Eligibility_All!$E:$E,"Not Found",0) -> 46188 | L8: =_xlfn.XLOOKUP($C8,Eligibility_All!$B:$B,Eligibility_All!$F:$F,"Not Found",0) -> Yes | M8: =_xlfn.XLOOKUP($C8,Eligibility_All!$B:$B,Eligibility_All!$G:$G,"Not Found",0) -> Complete 5-year NAV history available
A9: 8 | B9: Large & Mid Cap Fund | C9: 146772 | D9: =_xlfn.XLOOKUP(tbl_Selected_Schemes[[#This Row],[Scheme_Code]],All_Schemes[Scheme_Code],All_Schemes[Scheme_Name],"Not Found",0) -> HSBC Large & Mid Cap Fund - Direct Growth | E9: {=IFERROR(_xlfn.XLOOKUP(TRUE,ISNUMBER(SEARCH(Lists!$H$2:$H$30,D9)),Lists!$I$2:$I$30),"Check Manually")} -> HSBC Mutual Fund | F9: Direct | G9: Growth | H9: Yes | J9: =_xlfn.XLOOKUP($C9,Eligibility_All!$B:$B,Eligibility_All!$D:$D,"Not Found",0) -> 43559 | K9: =_xlfn.XLOOKUP($C9,Eligibility_All!$B:$B,Eligibility_All!$E:$E,"Not Found",0) -> 46188 | L9: =_xlfn.XLOOKUP($C9,Eligibility_All!$B:$B,Eligibility_All!$F:$F,"Not Found",0) -> Yes | M9: =_xlfn.XLOOKUP($C9,Eligibility_All!$B:$B,Eligibility_All!$G:$G,"Not Found",0) -> Complete 5-year NAV history available
A10: 9 | B10: Large & Mid Cap Fund | C10: 118419 | D10: =_xlfn.XLOOKUP(tbl_Selected_Schemes[[#This Row],[Scheme_Code]],All_Schemes[Scheme_Code],All_Schemes[Scheme_Name],"Not Found",0) -> Bandhan Large & Mid Cap Fund - Direct Plan - Growth | E10: {=IFERROR(_xlfn.XLOOKUP(TRUE,ISNUMBER(SEARCH(Lists!$H$2:$H$30,D10)),Lists!$I$2:$I$30),"Check Manually")} -> Bandhan Mutual Fund | F10: Direct | G10: Growth | H10: Yes | J10: =_xlfn.XLOOKUP($C10,Eligibility_All!$B:$B,Eligibility_All!$D:$D,"Not Found",0) -> 41276 | K10: =_xlfn.XLOOKUP($C10,Eligibility_All!$B:$B,Eligibility_All!$E:$E,"Not Found",0) -> 46188 | L10: =_xlfn.XLOOKUP($C10,Eligibility_All!$B:$B,Eligibility_All!$F:$F,"Not Found",0) -> Yes | M10: =_xlfn.XLOOKUP($C10,Eligibility_All!$B:$B,Eligibility_All!$G:$G,"Not Found",0) -> Complete 5-year NAV history available
A11: 10 | B11: Large & Mid Cap Fund | C11: 120826 | D11: =_xlfn.XLOOKUP(tbl_Selected_Schemes[[#This Row],[Scheme_Code]],All_Schemes[Scheme_Code],All_Schemes[Scheme_Name],"Not Found",0) -> quant Large & Mid Cap Fund - Growth Option-Direct Plan | E11: {=IFERROR(_xlfn.XLOOKUP(TRUE,ISNUMBER(SEARCH(Lists!$H$2:$H$30,D11)),Lists!$I$2:$I$30),"Check Manually")} -> Quant Mutual Fund | F11: Direct | G11: Growth | H11: Yes | J11: =_xlfn.XLOOKUP($C11,Eligibility_All!$B:$B,Eligibility_All!$D:$D,"Not Found",0) -> 41281 | K11: =_xlfn.XLOOKUP($C11,Eligibility_All!$B:$B,Eligibility_All!$E:$E,"Not Found",0) -> 46188 | L11: =_xlfn.XLOOKUP($C11,Eligibility_All!$B:$B,Eligibility_All!$F:$F,"Not Found",0) -> Yes | M11: =_xlfn.XLOOKUP($C11,Eligibility_All!$B:$B,Eligibility_All!$G:$G,"Not Found",0) -> Complete 5-year NAV history available
A12: 11 | B12: Mid Cap Fund | C12: 151036 | D12: =_xlfn.XLOOKUP(tbl_Selected_Schemes[[#This Row],[Scheme_Code]],All_Schemes[Scheme_Code],All_Schemes[Scheme_Name],"Not Found",0) -> HSBC Midcap Fund - Direct Growth | E12: {=IFERROR(_xlfn.XLOOKUP(TRUE,ISNUMBER(SEARCH(Lists!$H$2:$H$30,D12)),Lists!$I$2:$I$30),"Check Manually")} -> HSBC Mutual Fund | F12: Direct | G12: Growth | H12: No | J12: =_xlfn.XLOOKUP($C12,Eligibility_All!$B:$B,Eligibility_All!$D:$D,"Not Found",0) -> 44893 | K12: =_xlfn.XLOOKUP($C12,Eligibility_All!$B:$B,Eligibility_All!$E:$E,"Not Found",0) -> 46188 | L12: =_xlfn.XLOOKUP($C12,Eligibility_All!$B:$B,Eligibility_All!$F:$F,"Not Found",0) -> No | M12: =_xlfn.XLOOKUP($C12,Eligibility_All!$B:$B,Eligibility_All!$G:$G,"Not Found",0) -> Complete 5-year NAV history not available
A13: 12 | B13: Mid Cap Fund | C13: 120381 | D13: =_xlfn.XLOOKUP(tbl_Selected_Schemes[[#This Row],[Scheme_Code]],All_Schemes[Scheme_Code],All_Schemes[Scheme_Name],"Not Found",0) -> ICICI Prudential MidCap Fund - Direct Plan - Growth | E13: {=IFERROR(_xlfn.XLOOKUP(TRUE,ISNUMBER(SEARCH(Lists!$H$2:$H$30,D13)),Lists!$I$2:$I$30),"Check Manually")} -> ICICI Prudential Mutual Fund | F13: Direct | G13: Growth | H13: Yes | J13: =_xlfn.XLOOKUP($C13,Eligibility_All!$B:$B,Eligibility_All!$D:$D,"Not Found",0) -> 41276 | K13: =_xlfn.XLOOKUP($C13,Eligibility_All!$B:$B,Eligibility_All!$E:$E,"Not Found",0) -> 46188 | L13: =_xlfn.XLOOKUP($C13,Eligibility_All!$B:$B,Eligibility_All!$F:$F,"Not Found",0) -> Yes | M13: =_xlfn.XLOOKUP($C13,Eligibility_All!$B:$B,Eligibility_All!$G:$G,"Not Found",0) -> Complete 5-year NAV history available
... A19: 18 | B19: Small Cap Fund | C19: 145137 | D19: =_xlfn.XLOOKUP(tbl_Selected_Schemes[[#This Row],[Scheme_Code]],All_Schemes[Scheme_Code],All_Schemes[Scheme_Name],"Not Found",0) -> Invesco India Smallcap Fund - Direct Plan - Growth | E19: {=IFERROR(_xlfn.XLOOKUP(TRUE,ISNUMBER(SEARCH(Lists!$H$2:$H$30,D19)),Lists!$I$2:$I$30),"Check Manually")} -> Invesco Mutual Fund | F19: Direct | G19: Growth | H19: Yes | J19: =_xlfn.XLOOKUP($C19,Eligibility_All!$B:$B,Eligibility_All!$D:$D,"Not Found",0) -> 43406 | K19: =_xlfn.XLOOKUP($C19,Eligibility_All!$B:$B,Eligibility_All!$E:$E,"Not Found",0) -> 46188 | L19: =_xlfn.XLOOKUP($C19,Eligibility_All!$B:$B,Eligibility_All!$F:$F,"Not Found",0) -> Yes | M19: =_xlfn.XLOOKUP($C19,Eligibility_All!$B:$B,Eligibility_All!$G:$G,"Not Found",0) -> Complete 5-year NAV history available
A20: 19 | B20: Small Cap Fund | C20: 129649 | D20: =_xlfn.XLOOKUP(tbl_Selected_Schemes[[#This Row],[Scheme_Code]],All_Schemes[Scheme_Code],All_Schemes[Scheme_Name],"Not Found",0) -> Union Small Cap Fund - Direct Plan - Growth Option | E20: Union Mutual Fund | F20: Direct | G20: Growth | H20: Yes | J20: =_xlfn.XLOOKUP($C20,Eligibility_All!$B:$B,Eligibility_All!$D:$D,"Not Found",0) -> 41807 | K20: =_xlfn.XLOOKUP($C20,Eligibility_All!$B:$B,Eligibility_All!$E:$E,"Not Found",0) -> 46188 | L20: =_xlfn.XLOOKUP($C20,Eligibility_All!$B:$B,Eligibility_All!$F:$F,"Not Found",0) -> Yes | M20: =_xlfn.XLOOKUP($C20,Eligibility_All!$B:$B,Eligibility_All!$G:$G,"Not Found",0) -> Complete 5-year NAV history available
A21: 20 | B21: Small Cap Fund | C21: 120828 | D21: =_xlfn.XLOOKUP(tbl_Selected_Schemes[[#This Row],[Scheme_Code]],All_Schemes[Scheme_Code],All_Schemes[Scheme_Name],"Not Found",0) -> quant Small Cap Fund - Growth Option - Direct Plan | E21: {=IFERROR(_xlfn.XLOOKUP(TRUE,ISNUMBER(SEARCH(Lists!$H$2:$H$30,D21)),Lists!$I$2:$I$30),"Check Manually")} -> Quant Mutual Fund | F21: Direct | G21: Growth | H21: Yes | J21: =_xlfn.XLOOKUP($C21,Eligibility_All!$B:$B,Eligibility_All!$D:$D,"Not Found",0) -> 41281 | K21: =_xlfn.XLOOKUP($C21,Eligibility_All!$B:$B,Eligibility_All!$E:$E,"Not Found",0) -> 46188 | L21: =_xlfn.XLOOKUP($C21,Eligibility_All!$B:$B,Eligibility_All!$F:$F,"Not Found",0) -> Yes | M21: =_xlfn.XLOOKUP($C21,Eligibility_All!$B:$B,Eligibility_All!$G:$G,"Not Found",0) -> Complete 5-year NAV history available
A22: 21 | B22: Multi Cap Fund | C22: 141226 | D22: =_xlfn.XLOOKUP(tbl_Selected_Schemes[[#This Row],[Scheme_Code]],All_Schemes[Scheme_Code],All_Schemes[Scheme_Name],"Not Found",0) -> Mahindra Manulife Multi Cap Fund - Direct Plan -Growth | E22: {=IFERROR(_xlfn.XLOOKUP(TRUE,ISNUMBER(SEARCH(Lists!$H$2:$H$30,D22)),Lists!$I$2:$I$30),"Check Manually")} -> Mahindra Manulife Mutual Fund | F22: Direct | G22: Growth | H22: Yes | J22: =_xlfn.XLOOKUP($C22,Eligibility_All!$B:$B,Eligibility_All!$D:$D,"Not Found",0) -> 42873 | K22: =_xlfn.XLOOKUP($C22,Eligibility_All!$B:$B,Eligibility_All!$E:$E,"Not Found",0) -> 46188 | L22: =_xlfn.XLOOKUP($C22,Eligibility_All!$B:$B,Eligibility_All!$F:$F,"Not Found",0) -> Yes | M22: =_xlfn.XLOOKUP($C22,Eligibility_All!$B:$B,Eligibility_All!$G:$G,"Not Found",0) -> Complete 5-year NAV history available
A23: 22 | B23: Multi Cap Fund | C23: 118650 | D23: =_xlfn.XLOOKUP(tbl_Selected_Schemes[[#This Row],[Scheme_Code]],All_Schemes[Scheme_Code],All_Schemes[Scheme_Name],"Not Found",0) -> Nippon India Multi Cap Fund - Direct Plan Growth Plan - Growth Option | E23: {=IFERROR(_xlfn.XLOOKUP(TRUE,ISNUMBER(SEARCH(Lists!$H$2:$H$30,D23)),Lists!$I$2:$I$30),"Check Manually")} -> Nippon India Mutual Fund | F23: Direct | G23: Growth | H23: Yes | J23: =_xlfn.XLOOKUP($C23,Eligibility_All!$B:$B,Eligibility_All!$D:$D,"Not Found",0) -> 41276 | K23: =_xlfn.XLOOKUP($C23,Eligibility_All!$B:$B,Eligibility_All!$E:$E,"Not Found",0) -> 46188 | L23: =_xlfn.XLOOKUP($C23,Eligibility_All!$B:$B,Eligibility_All!$F:$F,"Not Found",0) -> Yes | M23: =_xlfn.XLOOKUP($C23,Eligibility_All!$B:$B,Eligibility_All!$G:$G,"Not Found",0) -> Complete 5-year NAV history available
A24: 23 | B24: Multi Cap Fund | C24: 120599 | D24: =_xlfn.XLOOKUP(tbl_Selected_Schemes[[#This Row],[Scheme_Code]],All_Schemes[Scheme_Code],All_Schemes[Scheme_Name],"Not Found",0) -> ICICI Prudential Multicap Fund - Direct Plan - Growth | E24: {=IFERROR(_xlfn.XLOOKUP(TRUE,ISNUMBER(SEARCH(Lists!$H$2:$H$30,D24)),Lists!$I$2:$I$30),"Check Manually")} -> ICICI Prudential Mutual Fund | F24: Direct | G24: Growth | H24: Yes | J24: =_xlfn.XLOOKUP($C24,Eligibility_All!$B:$B,Eligibility_All!$D:$D,"Not Found",0) -> 41276 | K24: =_xlfn.XLOOKUP($C24,Eligibility_All!$B:$B,Eligibility_All!$E:$E,"Not Found",0) -> 46188 | L24: =_xlfn.XLOOKUP($C24,Eligibility_All!$B:$B,Eligibility_All!$F:$F,"Not Found",0) -> Yes | M24: =_xlfn.XLOOKUP($C24,Eligibility_All!$B:$B,Eligibility_All!$G:$G,"Not Found",0) -> Complete 5-year NAV history available
A25: 24 | B25: Multi Cap Fund | C25: 147183 | D25: =_xlfn.XLOOKUP(tbl_Selected_Schemes[[#This Row],[Scheme_Code]],All_Schemes[Scheme_Code],All_Schemes[Scheme_Name],"Not Found",0) -> ITI Multi Cap Fund - Direct Plan - Growth Option | E25: {=IFERROR(_xlfn.XLOOKUP(TRUE,ISNUMBER(SEARCH(Lists!$H$2:$H$30,D25)),Lists!$I$2:$I$30),"Check Manually")} -> ITI Mutual Fund | F25: Direct | G25: Growth | H25: Yes | J25: =_xlfn.XLOOKUP($C25,Eligibility_All!$B:$B,Eligibility_All!$D:$D,"Not Found",0) -> 43601 | K25: =_xlfn.XLOOKUP($C25,Eligibility_All!$B:$B,Eligibility_All!$E:$E,"Not Found",0) -> 46188 | L25: =_xlfn.XLOOKUP($C25,Eligibility_All!$B:$B,Eligibility_All!$F:$F,"Not Found",0) -> Yes | M25: =_xlfn.XLOOKUP($C25,Eligibility_All!$B:$B,Eligibility_All!$G:$G,"Not Found",0) -> Complete 5-year NAV history available
A26: 25 | B26: Multi Cap Fund | C26: 119354 | D26: =_xlfn.XLOOKUP(tbl_Selected_Schemes[[#This Row],[Scheme_Code]],All_Schemes[Scheme_Code],All_Schemes[Scheme_Name],"Not Found",0) -> Baroda BNP Paribas MULTI CAP FUND - Direct Plan - Growth Option | E26: {=IFERROR(_xlfn.XLOOKUP(TRUE,ISNUMBER(SEARCH(Lists!$H$2:$H$30,D26)),Lists!$I$2:$I$30),"Check Manually")} -> Baroda BNP Paribas Mutual Fund | F26: Direct | G26: Growth | H26: Yes | J26: =_xlfn.XLOOKUP($C26,Eligibility_All!$B:$B,Eligibility_All!$D:$D,"Not Found",0) -> 41276 | K26: =_xlfn.XLOOKUP($C26,Eligibility_All!$B:$B,Eligibility_All!$E:$E,"Not Found",0) -> 46188 | L26: =_xlfn.XLOOKUP($C26,Eligibility_All!$B:$B,Eligibility_All!$F:$F,"Not Found",0) -> Yes | M26: =_xlfn.XLOOKUP($C26,Eligibility_All!$B:$B,Eligibility_All!$G:$G,"Not Found",0) -> Complete 5-year NAV history available
A27: 26 | B27: Flexi Cap Fund | C27: 148404 | D27: =_xlfn.XLOOKUP(tbl_Selected_Schemes[[#This Row],[Scheme_Code]],All_Schemes[Scheme_Code],All_Schemes[Scheme_Name],"Not Found",0) -> BANK OF INDIA Flexi Cap Fund Direct Plan -Growth | E27: {=IFERROR(_xlfn.XLOOKUP(TRUE,ISNUMBER(SEARCH(Lists!$H$2:$H$30,D27)),Lists!$I$2:$I$30),"Check Manually")} -> Bank of India Mutual Fund | F27: Direct | G27: Growth | H27: Yes | J27: =_xlfn.XLOOKUP($C27,Eligibility_All!$B:$B,Eligibility_All!$D:$D,"Not Found",0) -> 44013 | K27: =_xlfn.XLOOKUP($C27,Eligibility_All!$B:$B,Eligibility_All!$E:$E,"Not Found",0) -> 46188 | L27: =_xlfn.XLOOKUP($C27,Eligibility_All!$B:$B,Eligibility_All!$F:$F,"Not Found",0) -> Yes | M27: =_xlfn.XLOOKUP($C27,Eligibility_All!$B:$B,Eligibility_All!$G:$G,"Not Found",0) -> Complete 5-year NAV history available
A28: 27 | B28: Flexi Cap Fund | C28: 120843 | D28: =_xlfn.XLOOKUP(tbl_Selected_Schemes[[#This Row],[Scheme_Code]],All_Schemes[Scheme_Code],All_Schemes[Scheme_Name],"Not Found",0) -> quant Flexi Cap Fund - Growth Option-Direct Plan | E28: {=IFERROR(_xlfn.XLOOKUP(TRUE,ISNUMBER(SEARCH(Lists!$H$2:$H$30,D28)),Lists!$I$2:$I$30),"Check Manually")} -> Quant Mutual Fund | F28: Direct | G28: Growth | H28: Yes | J28: =_xlfn.XLOOKUP($C28,Eligibility_All!$B:$B,Eligibility_All!$D:$D,"Not Found",0) -> 41281 | K28: =_xlfn.XLOOKUP($C28,Eligibility_All!$B:$B,Eligibility_All!$E:$E,"Not Found",0) -> 46188 | L28: =_xlfn.XLOOKUP($C28,Eligibility_All!$B:$B,Eligibility_All!$F:$F,"Not Found",0) -> Yes | M28: =_xlfn.XLOOKUP($C28,Eligibility_All!$B:$B,Eligibility_All!$G:$G,"Not Found",0) -> Complete 5-year NAV history available
A29: 28 | B29: Flexi Cap Fund | C29: 118955 | D29: =_xlfn.XLOOKUP(tbl_Selected_Schemes[[#This Row],[Scheme_Code]],All_Schemes[Scheme_Code],All_Schemes[Scheme_Name],"Not Found",0) -> HDFC Flexi Cap Fund - Growth Option - Direct Plan | E29: {=IFERROR(_xlfn.XLOOKUP(TRUE,ISNUMBER(SEARCH(Lists!$H$2:$H$30,D29)),Lists!$I$2:$I$30),"Check Manually")} -> HDFC Mutual Fund | F29: Direct | G29: Growth | H29: Yes | J29: =_xlfn.XLOOKUP($C29,Eligibility_All!$B:$B,Eligibility_All!$D:$D,"Not Found",0) -> 41275 | K29: =_xlfn.XLOOKUP($C29,Eligibility_All!$B:$B,Eligibility_All!$E:$E,"Not Found",0) -> 46188 | L29: =_xlfn.XLOOKUP($C29,Eligibility_All!$B:$B,Eligibility_All!$F:$F,"Not Found",0) -> Yes | M29: =_xlfn.XLOOKUP($C29,Eligibility_All!$B:$B,Eligibility_All!$G:$G,"Not Found",0) -> Complete 5-year NAV history available
A30: 29 | B30: Flexi Cap Fund | C30: 120492 | D30: =_xlfn.XLOOKUP(tbl_Selected_Schemes[[#This Row],[Scheme_Code]],All_Schemes[Scheme_Code],All_Schemes[Scheme_Name],"Not Found",0) -> JM Flexicap Fund (Direct) - Growth Option | E30: {=IFERROR(_xlfn.XLOOKUP(TRUE,ISNUMBER(SEARCH(Lists!$H$2:$H$30,D30)),Lists!$I$2:$I$30),"Check Manually")} -> JM Financial Mutual Fund | F30: Direct | G30: Growth | H30: Yes | J30: =_xlfn.XLOOKUP($C30,Eligibility_All!$B:$B,Eligibility_All!$D:$D,"Not Found",0) -> 41276 | K30: =_xlfn.XLOOKUP($C30,Eligibility_All!$B:$B,Eligibility_All!$E:$E,"Not Found",0) -> 46188 | L30: =_xlfn.XLOOKUP($C30,Eligibility_All!$B:$B,Eligibility_All!$F:$F,"Not Found",0) -> Yes | M30: =_xlfn.XLOOKUP($C30,Eligibility_All!$B:$B,Eligibility_All!$G:$G,"Not Found",0) -> Complete 5-year NAV history available
A31: 30 | B31: Flexi Cap Fund | C31: 120046 | D31: =_xlfn.XLOOKUP(tbl_Selected_Schemes[[#This Row],[Scheme_Code]],All_Schemes[Scheme_Code],All_Schemes[Scheme_Name],"Not Found",0) -> HSBC Flexi Cap Fund - Direct Growth | E31: {=IFERROR(_xlfn.XLOOKUP(TRUE,ISNUMBER(SEARCH(Lists!$H$2:$H$30,D31)),Lists!$I$2:$I$30),"Check Manually")} -> HSBC Mutual Fund | F31: Direct | G31: Growth | H31: Yes | J31: =_xlfn.XLOOKUP($C31,Eligibility_All!$B:$B,Eligibility_All!$D:$D,"Not Found",0) -> 41276 | K31: =_xlfn.XLOOKUP($C31,Eligibility_All!$B:$B,Eligibility_All!$E:$E,"Not Found",0) -> 46188 | L31: =_xlfn.XLOOKUP($C31,Eligibility_All!$B:$B,Eligibility_All!$F:$F,"Not Found",0) -> Yes | M31: =_xlfn.XLOOKUP($C31,Eligibility_All!$B:$B,Eligibility_All!$G:$G,"Not Found",0) -> Complete 5-year NAV history available
A32: 31 | B32: Focused Fund | C32: 119727 | D32: =_xlfn.XLOOKUP(tbl_Selected_Schemes[[#This Row],[Scheme_Code]],All_Schemes[Scheme_Code],All_Schemes[Scheme_Name],"Not Found",0) -> SBI FOCUSED FUND - DIRECT PLAN -GROWTH | E32: {=IFERROR(_xlfn.XLOOKUP(TRUE,ISNUMBER(SEARCH(Lists!$H$2:$H$30,D32)),Lists!$I$2:$I$30),"Check Manually")} -> SBI Mutual Fund | F32: Direct | G32: Growth | H32: Yes | J32: =_xlfn.XLOOKUP($C32,Eligibility_All!$B:$B,Eligibility_All!$D:$D,"Not Found",0) -> 41276 | K32: =_xlfn.XLOOKUP($C32,Eligibility_All!$B:$B,Eligibility_All!$E:$E,"Not Found",0) -> 46188 | L32: =_xlfn.XLOOKUP($C32,Eligibility_All!$B:$B,Eligibility_All!$F:$F,"Not Found",0) -> Yes | M32: =_xlfn.XLOOKUP($C32,Eligibility_All!$B:$B,Eligibility_All!$G:$G,"Not Found",0) -> Complete 5-year NAV history available
... A117: 116 | B117: Banking & PSU Debt Fund | C117: 126940 | D117: =_xlfn.XLOOKUP(tbl_Selected_Schemes[[#This Row],[Scheme_Code]],All_Schemes[Scheme_Code],All_Schemes[Scheme_Name],"Not Found",0) -> UTI Banking & PSU Fund - Direct Plan - Growth Option | E117: {=IFERROR(_xlfn.XLOOKUP(TRUE,ISNUMBER(SEARCH(Lists!$H$2:$H$30,D117)),Lists!$I$2:$I$30),"Check Manually")} -> UTI Mutual Fund | F117: Direct | G117: Growth | H117: Yes | J117: =_xlfn.XLOOKUP($C117,Eligibility_All!$B:$B,Eligibility_All!$D:$D,"Not Found",0) -> 41676 | K117: =_xlfn.XLOOKUP($C117,Eligibility_All!$B:$B,Eligibility_All!$E:$E,"Not Found",0) -> 46188 | L117: =_xlfn.XLOOKUP($C117,Eligibility_All!$B:$B,Eligibility_All!$F:$F,"Not Found",0) -> Yes | M117: =_xlfn.XLOOKUP($C117,Eligibility_All!$B:$B,Eligibility_All!$G:$G,"Not Found",0) -> Complete 5-year NAV history available
A118: 117 | B118: Banking & PSU Debt Fund | C118: 148656 | D118: =_xlfn.XLOOKUP(tbl_Selected_Schemes[[#This Row],[Scheme_Code]],All_Schemes[Scheme_Code],All_Schemes[Scheme_Name],"Not Found",0) -> TRUSTMF BANKING & PSU FUND - DIRECT GROWTH | E118: {=IFERROR(_xlfn.XLOOKUP(TRUE,ISNUMBER(SEARCH(Lists!$H$2:$H$30,D118)),Lists!$I$2:$I$30),"Check Manually")} -> Trust Mutual Fund | F118: Direct | G118: Growth | H118: No | I118: Excluded: NAV data not available up to common analysis end date | J118: =_xlfn.XLOOKUP($C118,Eligibility_All!$B:$B,Eligibility_All!$D:$D,"Not Found",0) -> 44229 | K118: =_xlfn.XLOOKUP($C118,Eligibility_All!$B:$B,Eligibility_All!$E:$E,"Not Found",0) -> 46063 | L118: =_xlfn.XLOOKUP($C118,Eligibility_All!$B:$B,Eligibility_All!$F:$F,"Not Found",0) -> Yes | M118: =_xlfn.XLOOKUP($C118,Eligibility_All!$B:$B,Eligibility_All!$G:$G,"Not Found",0) -> Complete 5-year NAV history available
A119: 118 | B119: Banking & PSU Debt Fund | C119: 120256 | D119: =_xlfn.XLOOKUP(tbl_Selected_Schemes[[#This Row],[Scheme_Code]],All_Schemes[Scheme_Code],All_Schemes[Scheme_Name],"Not Found",0) -> ICICI Prudential Banking and PSU Debt Fund - Direct Plan - Growth | E119: {=IFERROR(_xlfn.XLOOKUP(TRUE,ISNUMBER(SEARCH(Lists!$H$2:$H$30,D119)),Lists!$I$2:$I$30),"Check Manually")} -> ICICI Prudential Mutual Fund | F119: Direct | G119: Growth | H119: Yes | J119: =_xlfn.XLOOKUP($C119,Eligibility_All!$B:$B,Eligibility_All!$D:$D,"Not Found",0) -> 41347 | K119: =_xlfn.XLOOKUP($C119,Eligibility_All!$B:$B,Eligibility_All!$E:$E,"Not Found",0) -> 46188 | L119: =_xlfn.XLOOKUP($C119,Eligibility_All!$B:$B,Eligibility_All!$F:$F,"Not Found",0) -> Yes | M119: =_xlfn.XLOOKUP($C119,Eligibility_All!$B:$B,Eligibility_All!$G:$G,"Not Found",0) -> Complete 5-year NAV history available
A120: 119 | B120: Banking & PSU Debt Fund | C120: 123693 | D120: =_xlfn.XLOOKUP(tbl_Selected_Schemes[[#This Row],[Scheme_Code]],All_Schemes[Scheme_Code],All_Schemes[Scheme_Name],"Not Found",0) -> Kotak Banking and PSU Debt Direct - Growth | E120: {=IFERROR(_xlfn.XLOOKUP(TRUE,ISNUMBER(SEARCH(Lists!$H$2:$H$30,D120)),Lists!$I$2:$I$30),"Check Manually")} -> Kotak Mahindra Mutual Fund | F120: Direct | G120: Growth | H120: Yes | J120: =_xlfn.XLOOKUP($C120,Eligibility_All!$B:$B,Eligibility_All!$D:$D,"Not Found",0) -> 41500 | K120: =_xlfn.XLOOKUP($C120,Eligibility_All!$B:$B,Eligibility_All!$E:$E,"Not Found",0) -> 46188 | L120: =_xlfn.XLOOKUP($C120,Eligibility_All!$B:$B,Eligibility_All!$F:$F,"Not Found",0) -> Yes | M120: =_xlfn.XLOOKUP($C120,Eligibility_All!$B:$B,Eligibility_All!$G:$G,"Not Found",0) -> Complete 5-year NAV history available
A121: 120 | B121: Banking & PSU Debt Fund | C121: 129008 | D121: =_xlfn.XLOOKUP(tbl_Selected_Schemes[[#This Row],[Scheme_Code]],All_Schemes[Scheme_Code],All_Schemes[Scheme_Name],"Not Found",0) -> Franklin India Banking & PSU Debt Fund - Direct - Growth | E121: {=IFERROR(_xlfn.XLOOKUP(TRUE,ISNUMBER(SEARCH(Lists!$H$2:$H$30,D121)),Lists!$I$2:$I$30),"Check Manually")} -> Franklin Templeton Mutual Fund | F121: Direct | G121: Growth | H121: Yes | J121: =_xlfn.XLOOKUP($C121,Eligibility_All!$B:$B,Eligibility_All!$D:$D,"Not Found",0) -> 41754 | K121: =_xlfn.XLOOKUP($C121,Eligibility_All!$B:$B,Eligibility_All!$E:$E,"Not Found",0) -> 46188 | L121: =_xlfn.XLOOKUP($C121,Eligibility_All!$B:$B,Eligibility_All!$F:$F,"Not Found",0) -> Yes | M121: =_xlfn.XLOOKUP($C121,Eligibility_All!$B:$B,Eligibility_All!$G:$G,"Not Found",0) -> Complete 5-year NAV history available
A122: 121 | B122: Gilt Fund | C122: 120590 | D122: =_xlfn.XLOOKUP(tbl_Selected_Schemes[[#This Row],[Scheme_Code]],All_Schemes[Scheme_Code],All_Schemes[Scheme_Name],"Not Found",0) -> ICICI Prudential Gilt Fund - Direct Plan - Growth | E122: {=IFERROR(_xlfn.XLOOKUP(TRUE,ISNUMBER(SEARCH(Lists!$H$2:$H$30,D122)),Lists!$I$2:$I$30),"Check Manually")} -> ICICI Prudential Mutual Fund | F122: Direct | G122: Growth | H122: Yes | J122: =_xlfn.XLOOKUP($C122,Eligibility_All!$B:$B,Eligibility_All!$D:$D,"Not Found",0) -> 41276 | K122: =_xlfn.XLOOKUP($C122,Eligibility_All!$B:$B,Eligibility_All!$E:$E,"Not Found",0) -> 46188 | L122: =_xlfn.XLOOKUP($C122,Eligibility_All!$B:$B,Eligibility_All!$F:$F,"Not Found",0) -> Yes | M122: =_xlfn.XLOOKUP($C122,Eligibility_All!$B:$B,Eligibility_All!$G:$G,"Not Found",0) -> Complete 5-year NAV history available
A123: 122 | B123: Gilt Fund | C123: 119707 | D123: =_xlfn.XLOOKUP(tbl_Selected_Schemes[[#This Row],[Scheme_Code]],All_Schemes[Scheme_Code],All_Schemes[Scheme_Name],"Not Found",0) -> SBI GILT FUND - DIRECT PLAN - GROWTH | E123: {=IFERROR(_xlfn.XLOOKUP(TRUE,ISNUMBER(SEARCH(Lists!$H$2:$H$30,D123)),Lists!$I$2:$I$30),"Check Manually")} -> SBI Mutual Fund | F123: Direct | G123: Growth | H123: Yes | J123: =_xlfn.XLOOKUP($C123,Eligibility_All!$B:$B,Eligibility_All!$D:$D,"Not Found",0) -> 41277 | K123: =_xlfn.XLOOKUP($C123,Eligibility_All!$B:$B,Eligibility_All!$E:$E,"Not Found",0) -> 46188 | L123: =_xlfn.XLOOKUP($C123,Eligibility_All!$B:$B,Eligibility_All!$F:$F,"Not Found",0) -> Yes | M123: =_xlfn.XLOOKUP($C123,Eligibility_All!$B:$B,Eligibility_All!$G:$G,"Not Found",0) -> Complete 5-year NAV history available
A124: 123 | B124: Gilt Fund | C124: 119116 | D124: =_xlfn.XLOOKUP(tbl_Selected_Schemes[[#This Row],[Scheme_Code]],All_Schemes[Scheme_Code],All_Schemes[Scheme_Name],"Not Found",0) -> HDFC Gilt Fund - Growth Option - Direct Plan | E124: {=IFERROR(_xlfn.XLOOKUP(TRUE,ISNUMBER(SEARCH(Lists!$H$2:$H$30,D124)),Lists!$I$2:$I$30),"Check Manually")} -> HDFC Mutual Fund | F124: Direct | G124: Growth | H124: Yes | J124: =_xlfn.XLOOKUP($C124,Eligibility_All!$B:$B,Eligibility_All!$D:$D,"Not Found",0) -> 41275 | K124: =_xlfn.XLOOKUP($C124,Eligibility_All!$B:$B,Eligibility_All!$E:$E,"Not Found",0) -> 46188 | L124: =_xlfn.XLOOKUP($C124,Eligibility_All!$B:$B,Eligibility_All!$F:$F,"Not Found",0) -> Yes | M124: =_xlfn.XLOOKUP($C124,Eligibility_All!$B:$B,Eligibility_All!$G:$G,"Not Found",0) -> Complete 5-year NAV history available
A125: 124 | B125: Gilt Fund | C125: 119759 | D125: =_xlfn.XLOOKUP(tbl_Selected_Schemes[[#This Row],[Scheme_Code]],All_Schemes[Scheme_Code],All_Schemes[Scheme_Name],"Not Found",0) -> Kotak Gilt-Investment Regular-Growth - Direct | E125: {=IFERROR(_xlfn.XLOOKUP(TRUE,ISNUMBER(SEARCH(Lists!$H$2:$H$30,D125)),Lists!$I$2:$I$30),"Check Manually")} -> Kotak Mahindra Mutual Fund | F125: Direct | G125: Growth | H125: Yes | J125: =_xlfn.XLOOKUP($C125,Eligibility_All!$B:$B,Eligibility_All!$D:$D,"Not Found",0) -> 41276 | K125: =_xlfn.XLOOKUP($C125,Eligibility_All!$B:$B,Eligibility_All!$E:$E,"Not Found",0) -> 46188 | L125: =_xlfn.XLOOKUP($C125,Eligibility_All!$B:$B,Eligibility_All!$F:$F,"Not Found",0) -> Yes | M125: =_xlfn.XLOOKUP($C125,Eligibility_All!$B:$B,Eligibility_All!$G:$G,"Not Found",0) -> Complete 5-year NAV history available
A126: 125 | B126: Gilt Fund | C126: 119605 | D126: =_xlfn.XLOOKUP(tbl_Selected_Schemes[[#This Row],[Scheme_Code]],All_Schemes[Scheme_Code],All_Schemes[Scheme_Name],"Not Found",0) -> Aditya Birla Sun Life Government Securities Fund - Growth - Direct Plan | E126: {=IFERROR(_xlfn.XLOOKUP(TRUE,ISNUMBER(SEARCH(Lists!$H$2:$H$30,D126)),Lists!$I$2:$I$30),"Check Manually")} -> Aditya Birla Sun Life Mutual Fund | F126: Direct | G126: Growth | H126: Yes | J126: =_xlfn.XLOOKUP($C126,Eligibility_All!$B:$B,Eligibility_All!$D:$D,"Not Found",0) -> 41276 | K126: =_xlfn.XLOOKUP($C126,Eligibility_All!$B:$B,Eligibility_All!$E:$E,"Not Found",0) -> 46188 | L126: =_xlfn.XLOOKUP($C126,Eligibility_All!$B:$B,Eligibility_All!$F:$F,"Not Found",0) -> Yes | M126: =_xlfn.XLOOKUP($C126,Eligibility_All!$B:$B,Eligibility_All!$G:$G,"Not Found",0) -> Complete 5-year NAV history available
A127: 126 | B127: Gold Category | C127: 112368 | D127: =_xlfn.XLOOKUP(tbl_Selected_Schemes[[#This Row],[Scheme_Code]],All_Schemes[Scheme_Code],All_Schemes[Scheme_Name],"Not Found",0) -> Invesco India Gold Exchange Traded Fund | E127: {=IFERROR(_xlfn.XLOOKUP(TRUE,ISNUMBER(SEARCH(Lists!$H$2:$H$30,D127)),Lists!$I$2:$I$30),"Check Manually")} -> Invesco Mutual Fund | F127: Direct | G127: Growth | H127: Yes | J127: =_xlfn.XLOOKUP($C127,Eligibility_All!$B:$B,Eligibility_All!$D:$D,"Not Found",0) -> 40256 | K127: =_xlfn.XLOOKUP($C127,Eligibility_All!$B:$B,Eligibility_All!$E:$E,"Not Found",0) -> 46188 | L127: =_xlfn.XLOOKUP($C127,Eligibility_All!$B:$B,Eligibility_All!$F:$F,"Not Found",0) -> Yes | M127: =_xlfn.XLOOKUP($C127,Eligibility_All!$B:$B,Eligibility_All!$G:$G,"Not Found",0) -> Complete 5-year NAV history available
A128: 127 | B128: Gold Category | C128: 151961 | D128: =_xlfn.XLOOKUP(tbl_Selected_Schemes[[#This Row],[Scheme_Code]],All_Schemes[Scheme_Code],All_Schemes[Scheme_Name],"Not Found",0) -> LIC MF Gold Exchange Traded Fund | E128: {=IFERROR(_xlfn.XLOOKUP(TRUE,ISNUMBER(SEARCH(Lists!$H$2:$H$30,D128)),Lists!$I$2:$I$30),"Check Manually")} -> LIC Mutual Fund | F128: Direct | G128: Growth | H128: No | J128: =_xlfn.XLOOKUP($C128,Eligibility_All!$B:$B,Eligibility_All!$D:$D,"Not Found",0) -> 45138 | K128: =_xlfn.XLOOKUP($C128,Eligibility_All!$B:$B,Eligibility_All!$E:$E,"Not Found",0) -> 46189 | L128: =_xlfn.XLOOKUP($C128,Eligibility_All!$B:$B,Eligibility_All!$F:$F,"Not Found",0) -> No | M128: =_xlfn.XLOOKUP($C128,Eligibility_All!$B:$B,Eligibility_All!$G:$G,"Not Found",0) -> Complete 5-year NAV history not available
A129: 128 | B129: Gold Category | C129: 105463 | D129: =_xlfn.XLOOKUP(tbl_Selected_Schemes[[#This Row],[Scheme_Code]],All_Schemes[Scheme_Code],All_Schemes[Scheme_Name],"Not Found",0) -> UTI GOLD Exchange Traded Fund | E129: {=IFERROR(_xlfn.XLOOKUP(TRUE,ISNUMBER(SEARCH(Lists!$H$2:$H$30,D129)),Lists!$I$2:$I$30),"Check Manually")} -> UTI Mutual Fund | F129: Direct | G129: Growth | H129: Yes | J129: =_xlfn.XLOOKUP($C129,Eligibility_All!$B:$B,Eligibility_All!$D:$D,"Not Found",0) -> 39185 | K129: =_xlfn.XLOOKUP($C129,Eligibility_All!$B:$B,Eligibility_All!$E:$E,"Not Found",0) -> 46188 | L129: =_xlfn.XLOOKUP($C129,Eligibility_All!$B:$B,Eligibility_All!$F:$F,"Not Found",0) -> Yes | M129: =_xlfn.XLOOKUP($C129,Eligibility_All!$B:$B,Eligibility_All!$G:$G,"Not Found",0) -> Complete 5-year NAV history available
...

Sheet Eligibility_All
A1: Category | B1: Scheme_Code | C1: Scheme_Name | D1: NAV_Start_Date | E1: NAV_End_Date | F1: Five_Year_Eligible | G1: Eligibility_Remark
A2: Large Cap Fund | B2: 118632 | C2: Nippon India Large Cap Fund - Direct Plan Growth Plan - Growth Option | D2: 41276 | E2: 46188 | F2: Yes | G2: Complete 5-year NAV history available
A3: Large Cap Fund | B3: 120586 | C3: ICICI Prudential Large Cap Fund (erstwhile Bluechip Fund) - Direct Plan - Growth | D3: 41276 | E3: 46188 | F3: Yes | G3: Complete 5-year NAV history available
A4: Large Cap Fund | B4: 119018 | C4: HDFC Large Cap Fund - Growth Option - Direct Plan | D4: 41275 | E4: 46188 | F4: Yes | G4: Complete 5-year NAV history available
A5: Large Cap Fund | B5: 118269 | C5: CANARA ROBECO LARGE CAP FUND - DIRECT PLAN - GROWTH OPTION | D5: 41276 | E5: 46188 | F5: Yes | G5: Complete 5-year NAV history available
A6: Large Cap Fund | B6: 119598 | C6: SBI Large Cap FUND-DIRECT PLAN -GROWTH | D6: 41276 | E6: 46188 | F6: Yes | G6: Complete 5-year NAV history available
A7: Large & Mid Cap Fund | B7: 147704 | C7: Motilal Oswal Large and Midcap Fund - Direct Plan Growth | D7: 43760 | E7: 46188 | F7: Yes | G7: Complete 5-year NAV history available
A8: Large & Mid Cap Fund | B8: 120357 | C8: Invesco India Large & Mid Cap Fund - Direct Plan - Growth | D8: 41276 | E8: 46188 | F8: Yes | G8: Complete 5-year NAV history available
A9: Large & Mid Cap Fund | B9: 146772 | C9: HSBC Large & Mid Cap Fund - Direct Growth | D9: 43559 | E9: 46188 | F9: Yes | G9: Complete 5-year NAV history available
A10: Large & Mid Cap Fund | B10: 118419 | C10: Bandhan Large & Mid Cap Fund - Direct Plan - Growth | D10: 41276 | E10: 46188 | F10: Yes | G10: Complete 5-year NAV history available
A11: Large & Mid Cap Fund | B11: 120826 | C11: quant Large & Mid Cap Fund - Growth Option-Direct Plan | D11: 41281 | E11: 46188 | F11: Yes | G11: Complete 5-year NAV history available
A12: Mid Cap Fund | B12: 151036 | C12: HSBC Midcap Fund - Direct Growth | D12: 44893 | E12: 46188 | F12: No | G12: Complete 5-year NAV history not available
A13: Mid Cap Fund | B13: 120381 | C13: ICICI Prudential MidCap Fund - Direct Plan - Growth | D13: 41276 | E13: 46188 | F13: Yes | G13: Complete 5-year NAV history available
... A163: Banking & PSU Debt Fund | B163: 120438 | C163: Axis Banking & PSU Debt Fund - Direct Plan - Growth Option | D163: 41276 | E163: 46189 | F163: Yes | G163: Complete 5-year NAV history available

Sheet All_Schemes
A1: Scheme_Code | B1: Scheme_Name | C1: isinGrowth | D1: isinDivReinvestment
A2: 100027 | B2: Grindlays Super Saver Income Fund-GSSIF-Half Yearly Dividend
A3: 100028 | B3: Grindlays Super Saver Income Fund-GSSIF-Quaterly Dividend
A4: 100029 | B4: Grindlays Super Saver Income Fund-GSSIF-Growth
A5: 100030 | B5: Grindlays Super Saver Income Fund-GSSIF-Annual Dividend
A6: 100031 | B6: Grindlays Super Saver Income Fund-GSSIF - ST-Dividend
A7: 100032 | B7: Grindlays Super Saver Income Fund-GSSIF - ST-Growth
A8: 100033 | B8: Aditya Birla Sun Life Large & Mid Cap Fund - Regular Growth | C8: INF209K01165
A9: 100034 | B9: Aditya Birla Sun Life Large & Mid Cap Fund -Regular - IDCW | C9: INF209K01157 | D9: INF209K01CE5
A10: 100035 | B10: Birla Sun Life Freedom Fund-Plan A (Dividend)
A11: 100036 | B11: Birla Sun Life Freedom Fund-Plan B (Growth)
A12: 100037 | B12: Aditya Birla Sun Life Income Fund - Regular - Quarterly IDCW | C12: INF209K01587 | D12: INF209K01CY3
A13: 100038 | B13: Aditya Birla Sun Life Income Fund - Growth - Regular Plan | C13: INF209K01579
A14: 100041 | B14: Aditya Birla Sun Life Liquid Fund -Institutional - IDCW | D14: INF209K01KN9
A15: 100042 | B15: Aditya Birla Sun Life Liquid Fund-Retail (Growth) | C15: INF209K01ME4
A16: 100043 | B16: Aditya Birla Sun Life Liquid Fund-Institutional (Growth) | C16: INF209K01RT1
A17: 100044 | B17: Aditya Birla Sun Life Liquid Fund -Retail - IDCW | D17: INF209K01KP4
A18: 100046 | B18: Aditya Birla Sun Life Liquid Fund -Daily IDCW | C18: INF209K01KQ2 | D18: INF209K01SQ5
A19: 100047 | B19: Aditya Birla Sun Life Liquid Fund - Growth | C19: INF209K01RU9
A20: 100048 | B20: Aditya Birla Sun Life Liquid Fund -Institutional - weekly IDCW | C20: INF209KA1LK7 | D20: INF209K01KY6
A21: 100049 | B21: Aditya Birla Sun Life Cash Plus-Institutional - Fortnightly Dividend
A22: 100051 | B22: Aditya Birla Sun Life Liquid Fund -weekly IDCW | C22: INF209K01KU4 | D22: INF209KA1LJ9
A23: 100052 | B23: Aditya Birla Sun Life Cash Plus-Institutional Premium - Fortnightly Dividend
A24: 100053 | B24: Aditya Birla Sun Life Cash Plus-Institutional Premium Plan-Monthly Dividend
A25: 100054 | B25: Aditya Birla Sun Life Gilt Plus - Liquid Plan - Quarterly Dividend - Regular Plan
A26: 100055 | B26: Aditya Birla Sun Life Gilt Plus - Liquid Plan - Growth - Regular Plan
A27: 100056 | B27: Aditya Birla Sun Life Gilt Plus - Liquid Plan - Annual Dividend - Regular Plan
A28: 100057 | B28: Aditya Birla Sun Life Govenment Securities Fund -Regular - Quarterly IDCW | C28: INF209K01AF6 | D28: INF209K01DP9
A29: 100058 | B29: Aditya Birla Sun Life Government Securities Fund - Growth - Regular Plan | C29: INF209K01AC3 | D29: INF209K01AD1
A30: 100059 | B30: Aditya Birla Sun Life Gilt Plus-PF Plan (Annual Dividend)
A31: 100060 | B31: Aditya Birla Sun Life Constant Maturity 10 Year Gilt Fund - Quarterly Dividend - Regular Plan
A32: 100061 | B32: Aditya Birla Sun Life Constant Maturity 10 Year Gilt Fund - Growth - Regular Plan
A33: 100062 | B33: Aditya Birla Sun Life Gilt Plus-Regular Plan (Annual Dividend)
A34: 100063 | B34: Aditya Birla Sun Life MNC Fund - Regular - IDCW | C34: INF209K01314 | D34: INF209K01CL0
A35: 100064 | B35: Aditya Birla Sun Life MNC Fund - Growth - Regular Plan | C35: INF209K01322
A36: 100065 | B36: Aditya Birla Sun Life India Opportunities Fund - Dividend - Regular Plan
A37: 100066 | B37: Aditya Birla Sun Life India Opportunities Fund - Growth - Regular Plan
A38: 100067 | B38: Aditya Birla Sun Life Tax Plan -Regular - IDCW
A39: 100068 | B39: BARODA ELSS 96 - Plan A - IDCW
A40: 100069 | B40: BARODA PIONEER DIVERSIFIED FUND
...

Sheet Eligible_Direct_Growth
A1: Scheme_Code | B1: Scheme_Name | C1: isinGrowth | D1: isinDivReinvestment
A2: 103490 | B2: Quantum Value Fund - Direct Plan Growth Option | C2: INF082J01036
A3: 103734 | B3: Quantum Liquid Fund - Direct Plan Growth Option | C3: INF082J01127
A4: 111549 | B4: Quantum ELSS Tax Saver Fund - Direct Plan Growth Option | C4: INF082J01069
A5: 112039 | B5: Quantum Diversified Equity All Cap Active FOF - Direct Plan Growth Option | C5: INF082J01093
A6: 115132 | B6: Quantum Gold Savings Fund - Direct Plan Growth Option | C6: INF082J01150
A7: 117608 | B7: Quantum Multi Asset Active FOF - Direct Plan Growth Option | C7: INF082J01168
A8: 118267 | B8: CANARA ROBECO INFRASTRUCTURE FUND - DIRECT PLAN - GROWTH OPTION | C8: INF760K01FO9
A9: 118269 | B9: CANARA ROBECO LARGE CAP FUND - DIRECT PLAN - GROWTH OPTION | C9: INF760K01FR2
A10: 118272 | B10: CANARA ROBECO EQUITY HYBRID FUND - DIRECT PLAN - GROWTH OPTION | C10: INF760K01EZ8
A11: 118273 | B11: CANARA ROBECO CONSUMPTION FUND - DIRECT PLAN - GROWTH OPTION | C11: INF760K01DU1
A12: 118275 | B12: CANARA ROBECO FLEXICAP FUND - DIRECT PLAN - GROWTH OPTION | C12: INF760K01EF0
A13: 118278 | B13: CANARA ROBECO LARGE AND MID CAP FUND - DIRECT PLAN - GROWTH OPTION | C13: INF760K01EI4
... A118: 118859 | B118: Mirae Asset Liquid Fund - Direct Plan - Growth | C118: INF769K01CM1
A119: 118866 | B119: Taurus ELSS Tax Saver Fund - Direct Plan - Growth | C119: INF044D01CG6 | D119: INF044D01AA3
A120: 118868 | B120: Taurus Banking & Financial Services Fund - Direct Plan - Growth | C120: INF044D01CN2
A121: 118870 | B121: Taurus Large Cap Fund - Direct Plan - Growth | C121: INF044D01BX3
A122: 118872 | B122: Taurus Mid Cap Fund - Direct Plan - Growth | C122: INF044D01CA9
A123: 118876 | B123: Taurus Ethical Fund - Direct Plan - Growth | C123: INF044D01CJ0
A124: 118879 | B124: Taurus Infrastructure Fund - Direct Plan - Growth | C124: INF044D01CD3
A125: 118881 | B125: Taurus Nifty 50 Index Fund - Direct Plan - Growth | C125: INF044D01CQ5
A126: 118883 | B126: Taurus Flexi Cap Fund - Direct Plan - Growth | C126: INF044D01BU9
A127: 118924 | B127: DSP Bond Fund - Direct Plan - Growth | C127: INF740K01MZ3
A128: 118931 | B128: HDFC ARBITRAGE FUND - Growth Option - Direct Plan | C128: INF179K01UU8
A129: 118935 | B129: HDFC Value Fund - Growth Option - Direct Plan | C129: INF179K01VC4
A130: 118942 | B130: HDFC Low Duration Fund - Direct Plan - Growth | C130: INF179K01VF7
A131: 118950 | B131: HDFC Focused Fund - Growth Option - Direct Plan | C131: INF179K01VK7
... A368: 120475 | B368: Axis Strategic Bond Fund - Direct Plan - Growth Option | C368: INF846K01DT0
A369: 120478 | B369: Axis Conservative Hybrid Fund - Direct Plan - Half Yearly | C369: INF846K01EB6 | D369: INF846K01EC4
A370: 120479 | B370: Axis Conservative Hybrid Fund - Direct Plan - Quarterly | C370: INF846K01ED2 | D370: INF846K01EE0
A371: 120480 | B371: Axis Conservative Hybrid Fund - Direct Plan - Growth Option | C371: INF846K01EA8
A372: 120482 | B372: JM Arbitrage Fund (Direct) - Growth Option | C372: INF192K01BN6
A373: 120484 | B373: JM Aggressive Hybrid Fund (Direct) - Growth Option | C373: INF192K01BQ9
A374: 120486 | B374: JM Value Fund (Direct) - Growth Option | C374: INF192K01BT3
A375: 120488 | B375: JM Focused Fund (Direct) - Growth Option | C375: INF192K01BW7
A376: 120490 | B376: JM Large Cap Fund (Direct) - Growth Option | C376: INF192K01BZ0
A377: 120492 | B377: JM Flexicap Fund (Direct) - Growth Option | C377: INF192K01CC7
A378: 120494 | B378: JM ELSS Tax Saver Fund (Direct) - Growth Option | C378: INF192K01CE3
A379: 120497 | B379: Invesco India Corporate Bond Fund - Direct Plan - Growth | C379: INF205K01RF8
A380: 120503 | B380: Axis ELSS Tax Saver Fund - Direct Plan - Growth Option | C380: INF846K01EW2
...

Sheet Lists
A1: Category | H1: Fund_Keyword | I1: AMC_Name
A2: Large Cap Fund | H2: Aditya Birla Sun Life | I2: Aditya Birla Sun Life Mutual Fund
A3: Large & Mid Cap Fund | H3: Axis | I3: Axis Mutual Fund
A4: Mid Cap Fund | H4: Bandhan | I4: Bandhan Mutual Fund
A5: Small Cap Fund | H5: BANK OF INDIA | I5: Bank of India Mutual Fund
A6: Multi Cap Fund | H6: Baroda BNP Paribas | I6: Baroda BNP Paribas Mutual Fund
A7: Flexi Cap Fund | H7: Canara Robeco | I7: Canara Robeco Mutual Fund
A8: Focused Fund | H8: Edelweiss | I8: Edelweiss Mutual Fund
A9: Value Fund | H9: Franklin India | I9: Franklin Templeton Mutual Fund
A10: Dividend Yield Fund | H10: Templeton India | I10: Franklin Templeton Mutual Fund
A11: ELSS – Tax Saver Fund | H11: HDFC | I11: HDFC Mutual Fund
A12: Conservative Hybrid Fund | H12: HSBC | I12: HSBC Mutual Fund
... A29: Technology / IT Fund | H29: UTI | I29: UTI Mutual Fund
A30: Pharma & Healthcare Fund
A31: Children's Fund
A32: Retirement Fund
